Traceback (most recent call last):
  File "/usr/local/lib/python3.7/dist-packages/jupyter_cache/executors/utils.py", line 56, in single_nb_execution
    record_timing=False,
  File "/usr/local/lib/python3.7/dist-packages/nbclient/client.py", line 1204, in execute
    return NotebookClient(nb=nb, resources=resources, km=km, **kwargs).execute()
  File "/usr/local/lib/python3.7/dist-packages/nbclient/util.py", line 84, in wrapped
    return just_run(coro(*args, **kwargs))
  File "/usr/local/lib/python3.7/dist-packages/nbclient/util.py", line 62, in just_run
    return loop.run_until_complete(coro)
  File "/usr/lib/python3.7/asyncio/base_events.py", line 587, in run_until_complete
    return future.result()
  File "/usr/local/lib/python3.7/dist-packages/nbclient/client.py", line 664, in async_execute
    cell, index, execution_count=self.code_cells_executed + 1
  File "/usr/local/lib/python3.7/dist-packages/nbclient/client.py", line 965, in async_execute_cell
    await self._check_raise_for_error(cell, cell_index, exec_reply)
  File "/usr/local/lib/python3.7/dist-packages/nbclient/client.py", line 862, in _check_raise_for_error
    raise CellExecutionError.from_cell_and_msg(cell, exec_reply_content)
nbclient.exceptions.CellExecutionError: An error occurred while executing the following cell:
------------------
error = []

for i in range(1, 10):
    knn = KNeighborsClassifier(n_neighbors=i)
    knn.fit(X_train, y_train)

    pred_i = knn.predict(X_test)
    error.append(np.mean(pred_i != y_test))

plt.figure()
plt.plot(range(1, 26), error, color='red', marker='o',
         markerfacecolor='blue', markersize=10)
plt.title('Rata-Rata Error terhadap nilai K')
plt.xlabel('Nilai K')
plt.ylabel('Rata-Rata Error')
plt.show()
------------------

[0;31m[0m
[0;31mValueError[0mTraceback (most recent call last)
[0;32m<ipython-input-8-17eabd6774b9>[0m in [0;36m<module>[0;34m[0m
[1;32m     10[0m [0mplt[0m[0;34m.[0m[0mfigure[0m[0;34m([0m[0;34m)[0m[0;34m[0m[0;34m[0m[0m
[1;32m     11[0m plt.plot(range(1, 26), error, color='red', marker='o',
[0;32m---> 12[0;31m          markerfacecolor='blue', markersize=10)
[0m[1;32m     13[0m [0mplt[0m[0;34m.[0m[0mtitle[0m[0;34m([0m[0;34m'Rata-Rata Error terhadap nilai K'[0m[0;34m)[0m[0;34m[0m[0;34m[0m[0m
[1;32m     14[0m [0mplt[0m[0;34m.[0m[0mxlabel[0m[0;34m([0m[0;34m'Nilai K'[0m[0;34m)[0m[0;34m[0m[0;34m[0m[0m

[0;32m/usr/local/lib/python3.7/dist-packages/matplotlib/pyplot.py[0m in [0;36mplot[0;34m(scalex, scaley, data, *args, **kwargs)[0m
[1;32m   2761[0m     return gca().plot(
[1;32m   2762[0m         *args, scalex=scalex, scaley=scaley, **({"data": data} if data
[0;32m-> 2763[0;31m         is not None else {}), **kwargs)
[0m[1;32m   2764[0m [0;34m[0m[0m
[1;32m   2765[0m [0;34m[0m[0m

[0;32m/usr/local/lib/python3.7/dist-packages/matplotlib/axes/_axes.py[0m in [0;36mplot[0;34m(self, scalex, scaley, data, *args, **kwargs)[0m
[1;32m   1645[0m         """
[1;32m   1646[0m         [0mkwargs[0m [0;34m=[0m [0mcbook[0m[0;34m.[0m[0mnormalize_kwargs[0m[0;34m([0m[0mkwargs[0m[0;34m,[0m [0mmlines[0m[0;34m.[0m[0mLine2D[0m[0;34m)[0m[0;34m[0m[0;34m[0m[0m
[0;32m-> 1647[0;31m         [0mlines[0m [0;34m=[0m [0;34m[[0m[0;34m*[0m[0mself[0m[0;34m.[0m[0m_get_lines[0m[0;34m([0m[0;34m*[0m[0margs[0m[0;34m,[0m [0mdata[0m[0;34m=[0m[0mdata[0m[0;34m,[0m [0;34m**[0m[0mkwargs[0m[0;34m)[0m[0;34m][0m[0;34m[0m[0;34m[0m[0m
[0m[1;32m   1648[0m         [0;32mfor[0m [0mline[0m [0;32min[0m [0mlines[0m[0;34m:[0m[0;34m[0m[0;34m[0m[0m
[1;32m   1649[0m             [0mself[0m[0;34m.[0m[0madd_line[0m[0;34m([0m[0mline[0m[0;34m)[0m[0;34m[0m[0;34m[0m[0m

[0;32m/usr/local/lib/python3.7/dist-packages/matplotlib/axes/_base.py[0m in [0;36m__call__[0;34m(self, *args, **kwargs)[0m
[1;32m    214[0m                 [0mthis[0m [0;34m+=[0m [0margs[0m[0;34m[[0m[0;36m0[0m[0;34m][0m[0;34m,[0m[0;34m[0m[0;34m[0m[0m
[1;32m    215[0m                 [0margs[0m [0;34m=[0m [0margs[0m[0;34m[[0m[0;36m1[0m[0;34m:[0m[0;34m][0m[0;34m[0m[0;34m[0m[0m
[0;32m--> 216[0;31m             [0;32myield[0m [0;32mfrom[0m [0mself[0m[0;34m.[0m[0m_plot_args[0m[0;34m([0m[0mthis[0m[0;34m,[0m [0mkwargs[0m[0;34m)[0m[0;34m[0m[0;34m[0m[0m
[0m[1;32m    217[0m [0;34m[0m[0m
[1;32m    218[0m     [0;32mdef[0m [0mget_next_color[0m[0;34m([0m[0mself[0m[0;34m)[0m[0;34m:[0m[0;34m[0m[0;34m[0m[0m

[0;32m/usr/local/lib/python3.7/dist-packages/matplotlib/axes/_base.py[0m in [0;36m_plot_args[0;34m(self, tup, kwargs)[0m
[1;32m    340[0m [0;34m[0m[0m
[1;32m    341[0m         [0;32mif[0m [0mx[0m[0;34m.[0m[0mshape[0m[0;34m[[0m[0;36m0[0m[0;34m][0m [0;34m!=[0m [0my[0m[0;34m.[0m[0mshape[0m[0;34m[[0m[0;36m0[0m[0;34m][0m[0;34m:[0m[0;34m[0m[0;34m[0m[0m
[0;32m--> 342[0;31m             raise ValueError(f"x and y must have same first dimension, but "
[0m[1;32m    343[0m                              f"have shapes {x.shape} and {y.shape}")
[1;32m    344[0m         [0;32mif[0m [0mx[0m[0;34m.[0m[0mndim[0m [0;34m>[0m [0;36m2[0m [0;32mor[0m [0my[0m[0;34m.[0m[0mndim[0m [0;34m>[0m [0;36m2[0m[0;34m:[0m[0;34m[0m[0;34m[0m[0m

[0;31mValueError[0m: x and y must have same first dimension, but have shapes (25,) and (9,)
ValueError: x and y must have same first dimension, but have shapes (25,) and (9,)

